<?xml version="1.0" encoding="UTF-8"?>
<!-- Generated by org.testng.reporters.JUnitXMLReporter -->
<testsuite ignored="5" hostname="DESKTOP-BG83L86" failures="1" tests="12" name="Test" time="10.195" errors="0" timestamp="2025-02-07T14:25:47 IST">
  <testcase classname="com.bank.api.tests.AuthenticationTests" name="testSignUp_alreadyExistUser" time="2.965"/>
  <testcase classname="com.bank.api.tests.AuthenticationTests" name="testLogin_invalidCredentials" time="1.473"/>
  <testcase classname="com.bank.api.tests.AuthenticationTests" name="testLogin_validCredentials" time="0.394"/>
  <testcase classname="com.bank.api.tests.AuthenticationTests" name="testForgotPassword_validEmail" time="0.739"/>
  <testcase classname="com.bank.api.tests.UserProfileManagementTests" name="verifyGetUserProfile" time="0.553"/>
  <testcase classname="com.bank.api.tests.UserProfileManagementTests" name="verifyUpdateUserProfileWithPutRequest" time="0.516"/>
  <testcase classname="com.bank.api.tests.UserProfileManagementTests" name="verifyUpdateUserProfileWithPatchRequest" time="0.474"/>
  <testcase classname="com.bank.api.tests.UserProfileManagementTests" name="verifyChangePassword" time="0.859"/>
  <testcase classname="com.bank.api.tests.UserProfileManagementTests" name="verifyDeleteUserProfile" time="0.537">
    <failure type="java.lang.AssertionError" message="expected [User profile deleted successfully] but found [{
    &amp;quot;timestamp&amp;quot;: &amp;quot;2025-02-07 08:55:45&amp;quot;,
    &amp;quot;status&amp;quot;: 500,
    &amp;quot;error&amp;quot;: &amp;quot;System Error&amp;quot;,
    &amp;quot;message&amp;quot;: &amp;quot;An unexpected error occurred&amp;quot;,
    &amp;quot;path&amp;quot;: &amp;quot;uri=/api/users/profile&amp;quot;,
    &amp;quot;solution&amp;quot;: &amp;quot;Please try again later or contact support&amp;quot;,
    &amp;quot;errorCode&amp;quot;: &amp;quot;SYS_001&amp;quot;
}]">
      <![CDATA[java.lang.AssertionError: expected [User profile deleted successfully] but found [{
    "timestamp": "2025-02-07 08:55:45",
    "status": 500,
    "error": "System Error",
    "message": "An unexpected error occurred",
    "path": "uri=/api/users/profile",
    "solution": "Please try again later or contact support",
    "errorCode": "SYS_001"
}]
at com.bank.api.tests.UserProfileManagementTests.verifyDeleteUserProfile(UserProfileManagementTests.java:143)
at java.base/java.util.ArrayList.forEach(ArrayList.java:1596)
... Removed 35 stack frames]]>
    </failure>
  </testcase> <!-- verifyDeleteUserProfile -->
  <testcase classname="com.bank.api.tests.AccountTests" name="verifyCreateUserAccount" time="0.553"/>
  <testcase classname="com.bank.api.tests.AccountTests" name="verifyGetUserAccountByAccountNumber" time="0.491"/>
  <testcase classname="com.bank.api.tests.AccountTests" name="verifyGetUserAccounts" time="0.444"/>
  <testcase classname="com.bank.api.base.BaseTest" name="@AfterSuite tearDown" time="0.0">
    <ignored/>
  </testcase> <!-- @AfterSuite tearDown -->
  <testcase classname="com.bank.api.tests.AuthenticationTests" name="testSignUp_validData" time="0.0">
    <ignored/>
  </testcase> <!-- testSignUp_validData -->
  <testcase classname="com.bank.api.base.BaseTest" name="@BeforeSuite extentReportSetup" time="0.0">
    <ignored/>
  </testcase> <!-- @BeforeSuite extentReportSetup -->
  <testcase classname="com.bank.api.base.BaseTest" name="@AfterSuite tearDown" time="0.0">
    <ignored/>
  </testcase> <!-- @AfterSuite tearDown -->
  <testcase classname="com.bank.api.base.BaseTest" name="@BeforeSuite extentReportSetup" time="0.0">
    <ignored/>
  </testcase> <!-- @BeforeSuite extentReportSetup -->
</testsuite> <!-- Test -->
